[2023-03-17T23:50:18.830+0000] {taskinstance.py:1083} INFO - Dependencies all met for <TaskInstance: First_DAG.bash_task_move manual__2023-03-17T23:50:15.904834+00:00 [queued]>
[2023-03-17T23:50:18.846+0000] {taskinstance.py:1083} INFO - Dependencies all met for <TaskInstance: First_DAG.bash_task_move manual__2023-03-17T23:50:15.904834+00:00 [queued]>
[2023-03-17T23:50:18.847+0000] {taskinstance.py:1279} INFO - 
--------------------------------------------------------------------------------
[2023-03-17T23:50:18.848+0000] {taskinstance.py:1280} INFO - Starting attempt 1 of 2
[2023-03-17T23:50:18.848+0000] {taskinstance.py:1281} INFO - 
--------------------------------------------------------------------------------
[2023-03-17T23:50:18.868+0000] {taskinstance.py:1300} INFO - Executing <Task(BashOperator): bash_task_move> on 2023-03-17 23:50:15.904834+00:00
[2023-03-17T23:50:18.883+0000] {standard_task_runner.py:55} INFO - Started process 3636 to run task
[2023-03-17T23:50:18.889+0000] {standard_task_runner.py:82} INFO - Running: ['***', 'tasks', 'run', 'First_DAG', 'bash_task_move', 'manual__2023-03-17T23:50:15.904834+00:00', '--job-id', '44', '--raw', '--subdir', 'DAGS_FOLDER/first.py', '--cfg-path', '/tmp/tmpzsdxrhv1']
[2023-03-17T23:50:18.891+0000] {standard_task_runner.py:83} INFO - Job 44: Subtask bash_task_move
[2023-03-17T23:50:19.013+0000] {task_command.py:388} INFO - Running <TaskInstance: First_DAG.bash_task_move manual__2023-03-17T23:50:15.904834+00:00 [running]> on host 12e59bc4b2cf
[2023-03-17T23:50:19.164+0000] {taskinstance.py:1509} INFO - Exporting the following env vars:
AIRFLOW_CTX_DAG_OWNER=***
AIRFLOW_CTX_DAG_ID=First_DAG
AIRFLOW_CTX_TASK_ID=bash_task_move
AIRFLOW_CTX_EXECUTION_DATE=2023-03-17T23:50:15.904834+00:00
AIRFLOW_CTX_TRY_NUMBER=1
AIRFLOW_CTX_DAG_RUN_ID=manual__2023-03-17T23:50:15.904834+00:00
[2023-03-17T23:50:19.165+0000] {subprocess.py:63} INFO - Tmp dir root location: 
 /tmp
[2023-03-17T23:50:19.167+0000] {subprocess.py:75} INFO - Running command: ['/bin/bash', '-c', 'cp /Users/yucel/Data_Center/DATA_LAKE/dataset_raw  /Users/yucel/Data_Center/CLEAN_DATA']
[2023-03-17T23:50:19.180+0000] {subprocess.py:86} INFO - Output:
[2023-03-17T23:50:19.183+0000] {subprocess.py:93} INFO - cp: cannot stat '/Users/yucel/Data_Center/DATA_LAKE/dataset_raw': No such file or directory
[2023-03-17T23:50:19.184+0000] {subprocess.py:97} INFO - Command exited with return code 1
[2023-03-17T23:50:19.196+0000] {taskinstance.py:1768} ERROR - Task failed with exception
Traceback (most recent call last):
  File "/home/airflow/.local/lib/python3.7/site-packages/airflow/operators/bash.py", line 197, in execute
    f"Bash command failed. The command returned a non-zero exit code {result.exit_code}."
airflow.exceptions.AirflowException: Bash command failed. The command returned a non-zero exit code 1.
[2023-03-17T23:50:19.201+0000] {taskinstance.py:1323} INFO - Marking task as UP_FOR_RETRY. dag_id=First_DAG, task_id=bash_task_move, execution_date=20230317T235015, start_date=20230317T235018, end_date=20230317T235019
[2023-03-17T23:50:19.215+0000] {standard_task_runner.py:105} ERROR - Failed to execute job 44 for task bash_task_move (Bash command failed. The command returned a non-zero exit code 1.; 3636)
[2023-03-17T23:50:19.260+0000] {local_task_job.py:208} INFO - Task exited with return code 1
[2023-03-17T23:50:19.293+0000] {taskinstance.py:2578} INFO - 0 downstream tasks scheduled from follow-on schedule check
