[2023-03-17T23:44:32.846+0000] {taskinstance.py:1083} INFO - Dependencies all met for <TaskInstance: First_DAG.bash_task_move manual__2023-03-17T23:44:29.212057+00:00 [queued]>
[2023-03-17T23:44:32.863+0000] {taskinstance.py:1083} INFO - Dependencies all met for <TaskInstance: First_DAG.bash_task_move manual__2023-03-17T23:44:29.212057+00:00 [queued]>
[2023-03-17T23:44:32.863+0000] {taskinstance.py:1279} INFO - 
--------------------------------------------------------------------------------
[2023-03-17T23:44:32.864+0000] {taskinstance.py:1280} INFO - Starting attempt 1 of 2
[2023-03-17T23:44:32.865+0000] {taskinstance.py:1281} INFO - 
--------------------------------------------------------------------------------
[2023-03-17T23:44:32.883+0000] {taskinstance.py:1300} INFO - Executing <Task(BashOperator): bash_task_move> on 2023-03-17 23:44:29.212057+00:00
[2023-03-17T23:44:32.894+0000] {standard_task_runner.py:82} INFO - Running: ['***', 'tasks', 'run', 'First_DAG', 'bash_task_move', 'manual__2023-03-17T23:44:29.212057+00:00', '--job-id', '40', '--raw', '--subdir', 'DAGS_FOLDER/first.py', '--cfg-path', '/tmp/tmpgqgh7ein']
[2023-03-17T23:44:32.891+0000] {standard_task_runner.py:55} INFO - Started process 3095 to run task
[2023-03-17T23:44:32.896+0000] {standard_task_runner.py:83} INFO - Job 40: Subtask bash_task_move
[2023-03-17T23:44:33.056+0000] {task_command.py:388} INFO - Running <TaskInstance: First_DAG.bash_task_move manual__2023-03-17T23:44:29.212057+00:00 [running]> on host 12e59bc4b2cf
[2023-03-17T23:44:33.179+0000] {taskinstance.py:1509} INFO - Exporting the following env vars:
AIRFLOW_CTX_DAG_OWNER=***
AIRFLOW_CTX_DAG_ID=First_DAG
AIRFLOW_CTX_TASK_ID=bash_task_move
AIRFLOW_CTX_EXECUTION_DATE=2023-03-17T23:44:29.212057+00:00
AIRFLOW_CTX_TRY_NUMBER=1
AIRFLOW_CTX_DAG_RUN_ID=manual__2023-03-17T23:44:29.212057+00:00
[2023-03-17T23:44:33.183+0000] {subprocess.py:63} INFO - Tmp dir root location: 
 /tmp
[2023-03-17T23:44:33.185+0000] {subprocess.py:75} INFO - Running command: ['/bin/bash', '-c', 'cp /Users/yucel/Data_Center/DATA_LAKE/dataset_raw  /Users/yucel/Data_Center/CLEAN_DATA']
[2023-03-17T23:44:33.199+0000] {subprocess.py:86} INFO - Output:
[2023-03-17T23:44:33.202+0000] {subprocess.py:93} INFO - cp: cannot stat '/Users/yucel/Data_Center/DATA_LAKE/dataset_raw': No such file or directory
[2023-03-17T23:44:33.203+0000] {subprocess.py:97} INFO - Command exited with return code 1
[2023-03-17T23:44:33.216+0000] {taskinstance.py:1768} ERROR - Task failed with exception
Traceback (most recent call last):
  File "/home/airflow/.local/lib/python3.7/site-packages/airflow/operators/bash.py", line 197, in execute
    f"Bash command failed. The command returned a non-zero exit code {result.exit_code}."
airflow.exceptions.AirflowException: Bash command failed. The command returned a non-zero exit code 1.
[2023-03-17T23:44:33.224+0000] {taskinstance.py:1323} INFO - Marking task as UP_FOR_RETRY. dag_id=First_DAG, task_id=bash_task_move, execution_date=20230317T234429, start_date=20230317T234432, end_date=20230317T234433
[2023-03-17T23:44:33.240+0000] {standard_task_runner.py:105} ERROR - Failed to execute job 40 for task bash_task_move (Bash command failed. The command returned a non-zero exit code 1.; 3095)
[2023-03-17T23:44:33.275+0000] {local_task_job.py:208} INFO - Task exited with return code 1
[2023-03-17T23:44:33.295+0000] {taskinstance.py:2578} INFO - 0 downstream tasks scheduled from follow-on schedule check
