[2023-03-17T23:37:03.106+0000] {taskinstance.py:1083} INFO - Dependencies all met for <TaskInstance: First_DAG.bash_task_move manual__2023-03-17T23:31:57.545581+00:00 [queued]>
[2023-03-17T23:37:03.121+0000] {taskinstance.py:1083} INFO - Dependencies all met for <TaskInstance: First_DAG.bash_task_move manual__2023-03-17T23:31:57.545581+00:00 [queued]>
[2023-03-17T23:37:03.122+0000] {taskinstance.py:1279} INFO - 
--------------------------------------------------------------------------------
[2023-03-17T23:37:03.123+0000] {taskinstance.py:1280} INFO - Starting attempt 2 of 2
[2023-03-17T23:37:03.124+0000] {taskinstance.py:1281} INFO - 
--------------------------------------------------------------------------------
[2023-03-17T23:37:03.141+0000] {taskinstance.py:1300} INFO - Executing <Task(BashOperator): bash_task_move> on 2023-03-17 23:31:57.545581+00:00
[2023-03-17T23:37:03.149+0000] {standard_task_runner.py:55} INFO - Started process 2355 to run task
[2023-03-17T23:37:03.153+0000] {standard_task_runner.py:82} INFO - Running: ['***', 'tasks', 'run', 'First_DAG', 'bash_task_move', 'manual__2023-03-17T23:31:57.545581+00:00', '--job-id', '27', '--raw', '--subdir', 'DAGS_FOLDER/first.py', '--cfg-path', '/tmp/tmp8zhuw1qx']
[2023-03-17T23:37:03.154+0000] {standard_task_runner.py:83} INFO - Job 27: Subtask bash_task_move
[2023-03-17T23:37:03.334+0000] {task_command.py:388} INFO - Running <TaskInstance: First_DAG.bash_task_move manual__2023-03-17T23:31:57.545581+00:00 [running]> on host 12e59bc4b2cf
[2023-03-17T23:37:03.425+0000] {taskinstance.py:1509} INFO - Exporting the following env vars:
AIRFLOW_CTX_DAG_OWNER=***
AIRFLOW_CTX_DAG_ID=First_DAG
AIRFLOW_CTX_TASK_ID=bash_task_move
AIRFLOW_CTX_EXECUTION_DATE=2023-03-17T23:31:57.545581+00:00
AIRFLOW_CTX_TRY_NUMBER=2
AIRFLOW_CTX_DAG_RUN_ID=manual__2023-03-17T23:31:57.545581+00:00
[2023-03-17T23:37:03.427+0000] {subprocess.py:63} INFO - Tmp dir root location: 
 /tmp
[2023-03-17T23:37:03.428+0000] {subprocess.py:75} INFO - Running command: ['/bin/bash', '-c', 'cp /Users/yucel/Data_Center/DATA_LAKE/dataset_raw.txt /Users/yucel/Data_Center/CLEAN_DATA']
[2023-03-17T23:37:03.444+0000] {subprocess.py:86} INFO - Output:
[2023-03-17T23:37:03.447+0000] {subprocess.py:93} INFO - cp: cannot stat '/Users/yucel/Data_Center/DATA_LAKE/dataset_raw.txt': No such file or directory
[2023-03-17T23:37:03.448+0000] {subprocess.py:97} INFO - Command exited with return code 1
[2023-03-17T23:37:03.464+0000] {taskinstance.py:1768} ERROR - Task failed with exception
Traceback (most recent call last):
  File "/home/airflow/.local/lib/python3.7/site-packages/airflow/operators/bash.py", line 197, in execute
    f"Bash command failed. The command returned a non-zero exit code {result.exit_code}."
airflow.exceptions.AirflowException: Bash command failed. The command returned a non-zero exit code 1.
[2023-03-17T23:37:03.469+0000] {taskinstance.py:1323} INFO - Marking task as FAILED. dag_id=First_DAG, task_id=bash_task_move, execution_date=20230317T233157, start_date=20230317T233703, end_date=20230317T233703
[2023-03-17T23:37:03.484+0000] {standard_task_runner.py:105} ERROR - Failed to execute job 27 for task bash_task_move (Bash command failed. The command returned a non-zero exit code 1.; 2355)
[2023-03-17T23:37:03.527+0000] {local_task_job.py:208} INFO - Task exited with return code 1
[2023-03-17T23:37:03.551+0000] {taskinstance.py:2578} INFO - 0 downstream tasks scheduled from follow-on schedule check
