[2023-03-17T00:02:07.692+0000] {taskinstance.py:1083} INFO - Dependencies all met for <TaskInstance: First_DAG.bash_task_move_data manual__2023-03-17T00:02:05.620983+00:00 [queued]>
[2023-03-17T00:02:07.701+0000] {taskinstance.py:1083} INFO - Dependencies all met for <TaskInstance: First_DAG.bash_task_move_data manual__2023-03-17T00:02:05.620983+00:00 [queued]>
[2023-03-17T00:02:07.702+0000] {taskinstance.py:1279} INFO - 
--------------------------------------------------------------------------------
[2023-03-17T00:02:07.702+0000] {taskinstance.py:1280} INFO - Starting attempt 1 of 2
[2023-03-17T00:02:07.703+0000] {taskinstance.py:1281} INFO - 
--------------------------------------------------------------------------------
[2023-03-17T00:02:07.717+0000] {taskinstance.py:1300} INFO - Executing <Task(BashOperator): bash_task_move_data> on 2023-03-17 00:02:05.620983+00:00
[2023-03-17T00:02:07.723+0000] {standard_task_runner.py:55} INFO - Started process 16718 to run task
[2023-03-17T00:02:07.726+0000] {standard_task_runner.py:82} INFO - Running: ['***', 'tasks', 'run', 'First_DAG', 'bash_task_move_data', 'manual__2023-03-17T00:02:05.620983+00:00', '--job-id', '39', '--raw', '--subdir', 'DAGS_FOLDER/first.py', '--cfg-path', '/tmp/tmp79deqmqn']
[2023-03-17T00:02:07.727+0000] {standard_task_runner.py:83} INFO - Job 39: Subtask bash_task_move_data
[2023-03-17T00:02:07.794+0000] {task_command.py:388} INFO - Running <TaskInstance: First_DAG.bash_task_move_data manual__2023-03-17T00:02:05.620983+00:00 [running]> on host e831dd1240d3
[2023-03-17T00:02:07.859+0000] {taskinstance.py:1509} INFO - Exporting the following env vars:
AIRFLOW_CTX_DAG_OWNER=***
AIRFLOW_CTX_DAG_ID=First_DAG
AIRFLOW_CTX_TASK_ID=bash_task_move_data
AIRFLOW_CTX_EXECUTION_DATE=2023-03-17T00:02:05.620983+00:00
AIRFLOW_CTX_TRY_NUMBER=1
AIRFLOW_CTX_DAG_RUN_ID=manual__2023-03-17T00:02:05.620983+00:00
[2023-03-17T00:02:07.861+0000] {subprocess.py:63} INFO - Tmp dir root location: 
 /tmp
[2023-03-17T00:02:07.862+0000] {subprocess.py:75} INFO - Running command: ['/bin/bash', '-c', 'cp \\Users\\yucel\\Data_Center\\Data Lake\\dataset_raw.txt  \\Users\\yucel\\Data_Center\\Clean Data']
[2023-03-17T00:02:07.871+0000] {subprocess.py:86} INFO - Output:
[2023-03-17T00:02:07.873+0000] {subprocess.py:93} INFO - cp: target 'Data' is not a directory
[2023-03-17T00:02:07.874+0000] {subprocess.py:97} INFO - Command exited with return code 1
[2023-03-17T00:02:07.883+0000] {taskinstance.py:1768} ERROR - Task failed with exception
Traceback (most recent call last):
  File "/home/airflow/.local/lib/python3.7/site-packages/airflow/operators/bash.py", line 197, in execute
    f"Bash command failed. The command returned a non-zero exit code {result.exit_code}."
airflow.exceptions.AirflowException: Bash command failed. The command returned a non-zero exit code 1.
[2023-03-17T00:02:07.887+0000] {taskinstance.py:1323} INFO - Marking task as UP_FOR_RETRY. dag_id=First_DAG, task_id=bash_task_move_data, execution_date=20230317T000205, start_date=20230317T000207, end_date=20230317T000207
[2023-03-17T00:02:07.899+0000] {standard_task_runner.py:105} ERROR - Failed to execute job 39 for task bash_task_move_data (Bash command failed. The command returned a non-zero exit code 1.; 16718)
[2023-03-17T00:02:07.938+0000] {local_task_job.py:208} INFO - Task exited with return code 1
[2023-03-17T00:02:07.954+0000] {taskinstance.py:2578} INFO - 0 downstream tasks scheduled from follow-on schedule check
